<?xml version="1.0" ?>
<!-- =================================================================================== -->
<!-- |    This document was autogenerated by xacro from /home/bot12/robot_ws/install/tb3_description/share/tb3_description/urdf/turtlebot3_burger_base.urdf.xacro | -->
<!-- |    EDITING THIS FILE BY HAND IS NOT RECOMMENDED                                 | -->
<!-- =================================================================================== -->
<robot name="turtlebot3_burger">
    <!-- Init colour -->
    <material name="black">
        <color rgba="0.0 0.0 0.0 1.0"/>
    </material>
    <material name="dark">
        <color rgba="0.3 0.3 0.3 1.0"/>
    </material>
    <material name="light_black">
        <color rgba="0.4 0.4 0.4 1.0"/>
    </material>
    <material name="blue">
        <color rgba="0.0 0.0 0.8 1.0"/>
    </material>
    <material name="green">
        <color rgba="0.0 0.8 0.0 1.0"/>
    </material>
    <material name="grey">
        <color rgba="0.5 0.5 0.5 1.0"/>
    </material>
    <material name="orange">
        <color rgba="1.0 0.4235294117647059 0.0392156862745098 1.0"/>
    </material>
    <material name="brown">
        <color rgba="0.8705882352941177 0.8117647058823529 0.7647058823529411 1.0"/>
    </material>
    <material name="silver">
        <color rgba="0.7529411764705882 0.7529411764705882 0.7529411764705882 1.0"/>
    </material>
    <material name="red">
        <color rgba="0.8 0.0 0.0 1.0"/>
    </material>
    <material name="white">
        <color rgba="1.0 1.0 1.0 1.0"/>
    </material>
    <!-- Base -->
    <link name="base_link">
        <visual>
            <origin rpy="0 0 0" xyz="0.0 0.0 0.0"/>
            <geometry>
                <mesh filename="file:///home/bot12/robot_ws/install/tb3_description/share/tb3_description/meshes/burger_base.stl" scale="0.001 0.001 0.001"/>
                <!-- make sure that the path points correctly to the mesh file -->
            </geometry>
            <material name="dark"/>
        </visual>
        <collision>
            <origin rpy="0 0 0" xyz="0.0 0.0 0.08"/>
            <geometry>
                <box size="0.17 0.16 0.16"/>
            </geometry>
        </collision>
    </link>
    <link name="base_footprint">
        <inertial>
            <origin rpy="0 0 0" xyz="0.0 0.0 0.0125"/>
            <mass value="1.5"/>
            <inertia ixx="0.0270833333" ixy="0.0" ixz="0.0" iyy="0.01215" iyz="0.0" izz="0.0270833333"/>
        </inertial>
    </link>
    <joint name="base_joint" type="fixed">
        <parent link="base_link"/>
        <child link="base_footprint"/>
        <origin rpy="0 0 0" xyz="0 0 -0.020"/>
    </joint>
    <link name="wheel_left_link">
        <visual>
            <origin rpy="0 0 0" xyz="0 0 0"/>
            <geometry>
                <mesh filename="file:///home/bot12/robot_ws/install/tb3_description/share/tb3_description/meshes/left_tire.stl" scale="0.001 0.001 0.001"/>
            </geometry>
            <material name="orange"/>
        </visual>
        <inertial>
            <origin xyz="0 0 0"/>
            <mass value="0.01"/>
            <inertia ixx="0.0000029925" ixy="0.0" ixz="0.0" iyy="0.0000029925" iyz="0.0" izz="0.000005445"/>
        </inertial>
        <collision>
            <origin rpy="1.5707963267948966 0 0" xyz="0 0 0"/>
            <geometry>
                <cylinder length="0.018" radius="0.033"/>
            </geometry>
        </collision>
    </link>
    <joint name="wheel_left_joint" type="continuous">
        <parent link="base_link"/>
        <child link="wheel_left_link"/>
        <origin rpy="0 0 0" xyz="0.0375 0.075 0.018"/>
        <axis xyz="0 1 0"/>
    </joint>
    <link name="wheel_right_link">
        <visual>
            <origin rpy="0 0 0" xyz="0 0 0"/>
            <geometry>
                <mesh filename="file:///home/bot12/robot_ws/install/tb3_description/share/tb3_description/meshes/right_tire.stl" scale="0.001 0.001 0.001"/>
            </geometry>
            <material name="orange"/>
        </visual>
        <inertial>
            <origin xyz="0 0 0"/>
            <mass value="0.01"/>
            <inertia ixx="0.0000029925" ixy="0.0" ixz="0.0" iyy="0.0000029925" iyz="0.0" izz="0.000005445"/>
        </inertial>
        <collision>
            <origin rpy="1.5707963267948966 0 0" xyz="0 0 0"/>
            <geometry>
                <cylinder length="0.018" radius="0.033"/>
            </geometry>
        </collision>
    </link>
    <joint name="wheel_right_joint" type="continuous">
        <parent link="base_link"/>
        <child link="wheel_right_link"/>
        <origin rpy="0 0 0" xyz="0.0375 -0.075 0.018"/>
        <axis xyz="0 1 0"/>
    </joint>
    <link name="caster_back_center_link">
        <visual>
            <origin rpy="0 0 0" xyz="0 0 0"/>
            <geometry>
                <sphere radius="0.005"/>
            </geometry>
        </visual>
        <inertial>
            <origin xyz="0 0 0"/>
            <mass value="0.01"/>
            <inertia ixx="0.00000001" ixy="0.0" ixz="0.0" iyy="0.00000001" iyz="0.0" izz="0.00000001"/>
        </inertial>
        <collision>
            <origin rpy="0 0 0" xyz="0 0 0"/>
            <geometry>
                <sphere radius="0.005"/>
            </geometry>
        </collision>
    </link>
    <joint name="caster_back_center_joint" type="fixed">
        <parent link="base_link"/>
        <child link="caster_back_center_link"/>
        <origin rpy="0 0 0" xyz="-0.04 0.0 0.0"/>
    </joint>
    <link name="camera_link">
        <visual>
            <origin rpy="1.5707963267948966 0.0 1.5707963267948966" xyz="-0.075 -0.005 -0.04"/>
            <geometry>
                <mesh filename="file:///home/bot12/robot_ws/install/tb3_description/share/tb3_description/meshes/webcam.stl" scale="0.0001 0.0001 0.0001"/>
            </geometry>
            <material name="silver"/>
        </visual>
        <collision>
            <origin rpy="1.5707963267948966 0.0 1.5707963267948966" xyz="-0.075 -0.005 -0.04"/>
            <geometry>
                <mesh filename="file:///home/bot12/robot_ws/install/tb3_description/share/tb3_description/meshes/webcam.stl" scale="0.0001 0.0001 0.0001"/>
            </geometry>
        </collision>
        <inertial>
            <origin xyz="0 0 0"/>
            <mass value="0.001"/>
            <inertia ixx="0.001" ixy="0.0" ixz="0.0" iyy="0.001" iyz="0.0" izz="0.001"/>
        </inertial>
    </link>
    <joint name="camera_base_joint" type="fixed">
        <parent link="base_link"/>
        <child link="camera_link"/>
        <origin rpy="0 0 0" xyz="0.065 0.0 0.095"/>
    </joint>
    <link name="camera_lens_link"/>
    <joint name="camera_lens_joint" type="fixed">
        <parent link="camera_link"/>
        <child link="camera_lens_link"/>
        <origin rpy="0 0 0" xyz="0.025 -0.015 0.02"/>
    </joint>
    <link name="laser_link">
        <visual>
            <origin rpy="1.5707963267948966 0 0" xyz="-0.037 0.037 -0.042"/>
            <geometry>
                <mesh filename="file:///home/bot12/robot_ws/install/tb3_description/share/tb3_description/meshes/RPLIDAR.stl" scale="0.001 0.001 0.001"/>
            </geometry>
            <material name="light_black"/>
        </visual>
        <inertial>
            <origin xyz="0 0 0"/>
            <mass value="0.2"/>
            <inertia ixx="0.001" ixy="0.0" ixz="0.0" iyy="0.001" iyz="0.0" izz="0.001"/>
        </inertial>
        <collision>
            <origin rpy="0 0 0" xyz="0.0 0.0 0.0"/>
            <geometry>
                <box size="0.09 0.056 0.073"/>
            </geometry>
        </collision>
    </link>
    <joint name="laser_joint" type="fixed">
        <parent link="base_link"/>
        <child link="laser_link"/>
        <origin rpy="0 0 0" xyz="-0.005 0.0 0.18"/>
    </joint>
    <!-- Plugins -->
</robot>
